Workbook

Sheet Cover
D4: VISTA ENERGY, S.A.B. de C.V.
D5: Integrated Financial Model · DCF & Comparable Valuation
D7: NYSE: VIST | BMV: VISTA | Oil & Gas E&P — Vaca Muerta, Argentina
B14: Prepared by: | D14: Andreas Santucci
B15: Date: | D15: June – July 2026
B16: Currency: | D16: US$ in thousands, unless otherwise noted
B17: Fiscal year end: | D17: December 31
B20: TABLE OF CONTENTS
B21: SHEET | D21: DESCRIPTION
B22: Outputs | D22: Operating & financial KPIs, valuation summary, DCF and sensitivity analysis.
B23: Model | D23: Integrated 3-statement model (Income Statement, Balance Sheet, Cash Flow), 2022A–2030E, with operating drivers.
B24: Imputs Drivers | D24: Forecast assumptions — Brent price scenarios (Best / Base / Worst) and production growth.
B25: Imput Historical | D25: Historical financials 2022–2025, sourced from SEC EDGAR 20-F filings (audited).
B28: COLOR LEGEND
B29: Blue = inputs / hardcoded assumptions
B30: Black = formulas / calculations
B31: Green = links to other worksheets
B32: Red = links to external files / sources
B33: Yellow fill = key assumption to review / update
B34: DATA SOURCES
B35: SEC EDGAR — Vista Energy Form 20-F (FY2022, FY2023, FY2025), audited financial statements. Market data as of June 2026.
B37: Disclaimer: Educational and illustrative purposes only; not investment advice or a recommendation.

Sheet Outputs
B3: OPERATIONAL METRICS
G5: 2022A | H5: 2023A | I5: 2024A | J5: 2025A | K5: 2026E | L5: 2027E | M5: 2028E | N5: 2029E | O5: 2030E
B7: Production | C7: boe/d | G7: =Model!G158 -> 48560 | H7: =Model!H158 -> 51149 | I7: =Model!I158 -> 69660 | J7: =Model!J158 -> 115479 | K7: =Model!K158 -> 132800.85 | L7: =Model!L158 -> 148736.95 | M7: =Model!M158 -> 163610.65 | N7: =Model!N158 -> 176699.5 | O7: =Model!O158 -> 187301.47
B8: Oil production | C8: bbl/d | H8: ='Imput Historical'!H232 -> 43287.671 | I8: ='Imput Historical'!I232 -> 60382.514 | J8: ='Imput Historical'!J232 -> 100000 | K8: =K7*'Imput Historical'!$J$234 -> 115000 | L8: =L7*'Imput Historical'!$J$234 -> 128800 | M8: =M7*'Imput Historical'!$J$234 -> 141680 | N8: =N7*'Imput Historical'!$J$234 -> 153014.4 | O8: =O7*'Imput Historical'!$J$234 -> 162195.26
B9: Gas & NGL production | C9: boe/d | H9: =H7-H8 -> 7861.3288 | I9: =I7-I8 -> 9277.4863 | J9: =J7-J8 -> 15479 | K9: =K7-K8 -> 17800.85 | L9: =L7-L8 -> 19936.952 | M9: =M7-M8 -> 21930.647 | N9: =N7-N8 -> 23685.099 | O9: =O7-O8 -> 25106.205
B10: Realized oil price | C10: $/bbl | G10: ='Imput Historical'!G219 -> 72.2 | H10: ='Imput Historical'!H219 -> 66.7 | I10: ='Imput Historical'!I219 -> 69.2 | J10: ='Imput Historical'!J219 -> 62.9 | K10: =Model!K156*('Imput Historical'!J219/'Imput Historical'!J218) -> 78.394428 | L10: =Model!L156*('Imput Historical'!$J$219/'Imput Historical'!$J$218) -> 75.627566 | M10: =Model!M156*('Imput Historical'!$J$219/'Imput Historical'!$J$218) -> 73.782991 | N10: =Model!N156*('Imput Historical'!$J$219/'Imput Historical'!$J$218) -> 71.938416 | O10: =Model!O156*('Imput Historical'!$J$219/'Imput Historical'!$J$218) -> 69.171554
B11: Lifting cost | C11: $/boe | G11: =Model!G157 -> 7.5 | H11: =Model!H157 -> 5.1 | I11: =Model!I157 -> 4.6 | J11: =Model!J157 -> 4.4 | K11: =Model!K157 -> 4.3 | L11: =Model!L157 -> 4.1 | M11: =Model!M157 -> 3.9 | N11: =Model!N157 -> 3.7 | O11: =Model!O157 -> 3.5
B12: Royalties & export duties | C12: $/boe | G12: =IFERROR(-Model!G13*1000/(G7*365),"") -> 10.645043 | H12: =IFERROR(-Model!H13*1000/(H7*365),"") -> 9.4707458 | I12: =IFERROR(-Model!I13*1000/(I7*365),"") -> 9.5945473 | J12: =IFERROR(-Model!J13*1000/(J7*365),"") -> 8.1933654 | K12: =IFERROR(-Model!K13*1000/(K7*365),"") -> 10.211672 | L12: =IFERROR(-Model!L13*1000/(L7*365),"") -> 9.8512605 | M12: =IFERROR(-Model!M13*1000/(M7*365),"") -> 9.6109858 | N12: =IFERROR(-Model!N13*1000/(N7*365),"") -> 9.3707112 | O12: =IFERROR(-Model!O13*1000/(O7*365),"") -> 9.0102992
B13: Selling expenses | C13: $/boe | G13: =IFERROR(-Model!G19*1000/(G7*365),"") -> 3.3797477 | H13: =IFERROR(-Model!H19*1000/(H7*365),"") -> 3.6847491 | I13: =IFERROR(-Model!I19*1000/(I7*365),"") -> 5.5193326 | J13: =IFERROR(-Model!J19*1000/(J7*365),"") -> 5.1737332 | K13: =IFERROR(-Model!K19*1000/(K7*365),"") -> 6.4482012 | L13: =IFERROR(-Model!L19*1000/(L7*365),"") -> 6.2206176 | M13: =IFERROR(-Model!M19*1000/(M7*365),"") -> 6.0688952 | N13: =IFERROR(-Model!N19*1000/(N7*365),"") -> 5.9171728 | O13: =IFERROR(-Model!O19*1000/(O7*365),"") -> 5.6895893
B14: Total cost per boe | C14: $/boe | G14: =IFERROR(G11+G12+G13,"") -> 21.524791 | H14: =IFERROR(H11+H12+H13,"") -> 18.255495 | I14: =IFERROR(I11+I12+I13,"") -> 19.71388 | J14: =IFERROR(J11+J12+J13,"") -> 17.767099 | K14: =IFERROR(K11+K12+K13,"") -> 20.959874 | L14: =IFERROR(L11+L12+L13,"") -> 20.171878 | M14: =IFERROR(M11+M12+M13,"") -> 19.579881 | N14: =IFERROR(N11+N12+N13,"") -> 18.987884 | O14: =IFERROR(O11+O12+O13,"") -> 18.199888
B15: EBITDA per boe | C15: $/boe | G15: =IFERROR(Model!G26*1000/(G7*365),"") -> 41.786013 | H15: =IFERROR(Model!H26*1000/(H7*365),"") -> 40.490193 | I15: =IFERROR(Model!I26*1000/(I7*365),"") -> 40.886891 | J15: =IFERROR(Model!J26*1000/(J7*365),"") -> 37.404417 | K15: =IFERROR(Model!K26*1000/(K7*365),"") -> 47.797925 | L15: =IFERROR(Model!L26*1000/(L7*365),"") -> 46.159561 | M15: =IFERROR(Model!M26*1000/(M7*365),"") -> 45.134519 | N15: =IFERROR(Model!N26*1000/(N7*365),"") -> 44.109477 | O15: =IFERROR(Model!O26*1000/(O7*365),"") -> 42.471113
B16: Net wells tied-in | C16: # | I16: ='Imput Historical'!I230 -> 50 | J16: ='Imput Historical'!J230 -> 74
B17: Oil / gas split and wells tied-in per FY2025 Form 20-F, which discloses 2023–2025 only. Forecast split holds the 2025 oil mix of 86.6% constant. Source data: Imput Historical rows 224–235.
B19: INCOME STATEMENT
G21: 2022A | H21: 2023A | I21: 2024A | J21: 2025A | K21: 2026E | L21: 2027E | M21: 2028E | N21: 2029E | O21: 2030E
B23: Revenue | C23: $M | G23: =Model!G7/1000 -> 1187.66 | H23: =Model!H7/1000 -> 1168.774 | I23: =Model!I7/1000 -> 1647.768 | J23: =Model!J7/1000 -> 2474.197 | K23: =Model!K7/1000 -> 3546.2281 | L23: =Model!L7/1000 -> 3831.5952 | M23: =Model!M7/1000 -> 4111.9558 | N23: =Model!N7/1000 -> 4329.8894 | O23: =Model!O7/1000 -> 4413.1565
B24: Cost of sales | C24: $M | G24: =(Model!G17-Model!G7)/1000 -> -557.424 | H24: =(Model!H17-Model!H7)/1000 -> -577.525 | I24: =(Model!I17-Model!I7)/1000 -> -830.025 | J24: =(Model!J17-Model!J7)/1000 -> -1299.167 | K24: =(Model!K17-Model!K7)/1000 -> -1553.3495 | L24: =(Model!L17-Model!L7)/1000 -> -1709.2402 | M24: =(Model!M17-Model!M7)/1000 -> -1853.7763 | N24: =(Model!N17-Model!N7)/1000 -> -1973.5794 | O24: =(Model!O17-Model!O7)/1000 -> -2053.5721
B25: Gross Profit | C25: $M | G25: =Model!G17/1000 -> 630.236 | H25: =Model!H17/1000 -> 591.249 | I25: =Model!I17/1000 -> 817.743 | J25: =Model!J17/1000 -> 1175.03 | K25: =Model!K17/1000 -> 1992.8786 | L25: =Model!L17/1000 -> 2122.3549 | M25: =Model!M17/1000 -> 2258.1795 | N25: =Model!N17/1000 -> 2356.31 | O25: =Model!O17/1000 -> 2359.5845
B26: Gross Margin | C26: % | G26: =IFERROR(Model!G17/Model!G7,"") -> 0.53065355 | H26: =IFERROR(Model!H17/Model!H7,"") -> 0.50587111 | I26: =IFERROR(Model!I17/Model!I7,"") -> 0.49627314 | J26: =IFERROR(Model!J17/Model!J7,"") -> 0.47491368 | K26: =IFERROR(Model!K17/Model!K7,"") -> 0.56197136 | L26: =IFERROR(Model!L17/Model!L7,"") -> 0.55390897 | M26: =IFERROR(Model!M17/Model!M7,"") -> 0.54917407 | N26: =IFERROR(Model!N17/Model!N7,"") -> 0.54419635 | O26: =IFERROR(Model!O17/Model!O7,"") -> 0.53467047
B27: Adjusted EBITDA | C27: $M | G27: =Model!G26/1000 -> 740.632 | H27: =Model!H26/1000 -> 755.927 | I27: =Model!I26/1000 -> 1039.586 | J27: =Model!J26/1000 -> 1576.59 | K27: =Model!K26/1000 -> 2316.8758 | L27: =Model!L26/1000 -> 2505.9558 | M27: =Model!M26/1000 -> 2695.3381 | N27: =Model!N26/1000 -> 2844.8547 | O27: =Model!O26/1000 -> 2903.5392
B28: EBITDA Margin | C28: % | G28: =IFERROR(Model!G26/Model!G7,"") -> 0.62360608 | H28: =IFERROR(Model!H26/Model!H7,"") -> 0.64676918 | I28: =IFERROR(Model!I26/Model!I7,"") -> 0.63090556 | J28: =IFERROR(Model!J26/Model!J7,"") -> 0.6372128 | K28: =IFERROR(Model!K26/Model!K7,"") -> 0.65333525 | L28: =IFERROR(Model!L26/Model!L7,"") -> 0.65402416 | M28: =IFERROR(Model!M26/Model!M7,"") -> 0.6554881 | N28: =IFERROR(Model!N26/Model!N7,"") -> 0.6570271 | O28: =IFERROR(Model!O26/Model!O7,"") -> 0.65792799
B29: D&A | C29: $M | G29: =Model!G14/1000 -> -234.862 | H29: =Model!H14/1000 -> -276.43 | I29: =Model!I14/1000 -> -437.699 | J29: =Model!J14/1000 -> -738.903 | K29: =Model!K14/1000 -> -848.26543 | L29: =Model!L14/1000 -> -950.05728 | M29: =Model!M14/1000 -> -1045.063 | N29: =Model!N14/1000 -> -1128.668 | O29: =Model!O14/1000 -> -1196.3881
B30: EBIT | C30: $M | G30: =Model!G27/1000 -> 529.147 | H30: =Model!H27/1000 -> 631.487 | I30: =Model!I27/1000 -> 625.39 | J30: =Model!J27/1000 -> 1250.83 | K30: =Model!K27/1000 -> 1468.6104 | L30: =Model!L27/1000 -> 1555.8985 | M30: =Model!M27/1000 -> 1650.2751 | N30: =Model!N27/1000 -> 1716.1867 | O30: =Model!O27/1000 -> 1707.1511
B31: EBIT Margin | C31: % | G31: =IFERROR(Model!G27/Model!G7,"") -> 0.44553744 | H31: =IFERROR(Model!H27/Model!H7,"") -> 0.54029864 | I31: =IFERROR(Model!I27/Model!I7,"") -> 0.37953765 | J31: =IFERROR(Model!J27/Model!J7,"") -> 0.50554988 | K31: =IFERROR(Model!K27/Model!K7,"") -> 0.41413309 | L31: =IFERROR(Model!L27/Model!L7,"") -> 0.4060707 | M31: =IFERROR(Model!M27/Model!M7,"") -> 0.4013358 | N31: =IFERROR(Model!N27/Model!N7,"") -> 0.39635808 | O31: =IFERROR(Model!O27/Model!O7,"") -> 0.3868322
B32: Net Income | C32: $M | G32: =Model!G42/1000 -> 269.535 | H32: =Model!H42/1000 -> 396.955 | I32: =Model!I42/1000 -> 477.521 | J32: =Model!J42/1000 -> 719.063 | K32: =Model!K42/1000 -> 873.74469 | L32: =Model!L42/1000 -> 948.48009 | M32: =Model!M42/1000 -> 1033.6708 | N32: =Model!N42/1000 -> 1104.8249 | O32: =Model!O42/1000 -> 1128.9243
B33: Net Income Margin | C33: % | G33: =IFERROR(Model!G42/Model!G7,"") -> 0.22694626 | H33: =IFERROR(Model!H42/Model!H7,"") -> 0.33963367 | I33: =IFERROR(Model!I42/Model!I7,"") -> 0.28979869 | J33: =IFERROR(Model!J42/Model!J7,"") -> 0.2906248 | K33: =IFERROR(Model!K42/Model!K7,"") -> 0.24638705 | L33: =IFERROR(Model!L42/Model!L7,"") -> 0.24754183 | M33: =IFERROR(Model!M42/Model!M7,"") -> 0.25138179 | N33: =IFERROR(Model!N42/Model!N7,"") -> 0.25516238 | O33: =IFERROR(Model!O42/Model!O7,"") -> 0.25580881
B34: EPS diluted | C34: $/share | G34: =Model!G47 -> 2.755 | H34: =Model!H47 -> 4 | I34: =Model!I47 -> 4.633 | J34: =Model!J47 -> 6.707 | K34: =Model!K47 -> 8.1497805 | L34: =Model!L47 -> 8.8468687 | M34: =Model!M47 -> 9.641478 | N34: =Model!N47 -> 10.305162 | O34: =Model!O47 -> 10.529947
B37: CASH FLOW STATEMENT
G39: 2022A | H39: 2023A | I39: 2024A | J39: 2025A | K39: 2026E | L39: 2027E | M39: 2028E | N39: 2029E | O39: 2030E
B41: Cash from Operations | C41: $M | G41: =Model!G130/1000 -> 689.771 | H41: =Model!H130/1000 -> 712.033 | I41: =Model!I130/1000 -> 959.026 | J41: =Model!J130/1000 -> 796.191 | K41: =Model!K130/1000 -> 1674.224 | L41: =Model!L130/1000 -> 1885.8171 | M41: =Model!M130/1000 -> 2066.2367 | N41: =Model!N130/1000 -> 2223.7785 | O41: =Model!O130/1000 -> 2321.6008
B42: Cash from Investing | C42: $M | G42: =Model!G136/1000 -> -582.712 | H42: =Model!H136/1000 -> -699.313 | I42: =Model!I136/1000 -> -1051.876 | J42: =Model!J136/1000 -> -2349.064 | K42: =Model!K136/1000 -> -1550 | L42: =Model!L136/1000 -> -1500 | M42: =Model!M136/1000 -> -1400 | N42: =Model!N136/1000 -> -1300 | O42: =Model!O136/1000 -> -1200
B43: of which CapEx | C43: $M | G43: =Model!G133/1000 -> -479.025 | H43: =Model!H133/1000 -> -688.437 | I43: =Model!I133/1000 -> -1052.53 | J43: =Model!J133/1000 -> -1455.411 | K43: =Model!K133/1000 -> -1550 | L43: =Model!L133/1000 -> -1500 | M43: =Model!M133/1000 -> -1400 | N43: =Model!N133/1000 -> -1300 | O43: =Model!O133/1000 -> -1200
B44: Cash from Financing | C44: $M | G44: =Model!G144/1000 -> -143.201 | H44: =Model!H144/1000 -> 19.556 | I44: =Model!I144/1000 -> 641.211 | J44: =Model!J144/1000 -> 1327.54 | K44: =Model!K144/1000 -> -350 | L44: =Model!L144/1000 -> -350 | M44: =Model!M144/1000 -> -350 | N44: =Model!N144/1000 -> -350 | O44: =Model!O144/1000 -> -350
B45: Change in Cash | C45: $M | G45: =Model!G146/1000 -> -36.142 | H45: =Model!H146/1000 -> 32.276 | I45: =Model!I146/1000 -> 548.361 | J45: =Model!J146/1000 -> -225.333 | K45: =Model!K146/1000 -> -225.77596 | L45: =Model!L146/1000 -> 35.817053 | M45: =Model!M146/1000 -> 316.23667 | N45: =Model!N146/1000 -> 573.7785 | O45: =Model!O146/1000 -> 771.60081
B46: Free Cash Flow (levered) | C46: $M | G46: =Model!G151/1000 -> 210.746 | H46: =Model!H151/1000 -> 23.596 | I46: =Model!I151/1000 -> -93.504 | J46: =Model!J151/1000 -> -659.22 | K46: =Model!K151/1000 -> 124.22404 | L46: =Model!L151/1000 -> 385.81705 | M46: =Model!M151/1000 -> 666.23667 | N46: =Model!N151/1000 -> 923.7785 | O46: =Model!O151/1000 -> 1121.6008
B47: FCF Margin | C47: % | G47: =IFERROR(Model!G151/Model!G7,"") -> 0.17744641 | H47: =IFERROR(Model!H151/Model!H7,"") -> 0.020188676 | I47: =IFERROR(Model!I151/Model!I7,"") -> -0.056745853 | J47: =IFERROR(Model!J151/Model!J7,"") -> -0.26643796 | K47: =IFERROR(Model!K151/Model!K7,"") -> 0.035029907 | L47: =IFERROR(Model!L151/Model!L7,"") -> 0.10069358 | M47: =IFERROR(Model!M151/Model!M7,"") -> 0.16202428 | N47: =IFERROR(Model!N151/Model!N7,"") -> 0.21334921 | O47: =IFERROR(Model!O151/Model!O7,"") -> 0.25414934
B50: BALANCE SHEET SUMMARY
G52: 2022A | H52: 2023A | I52: 2024A | J52: 2025A | K52: 2026E | L52: 2027E | M52: 2028E | N52: 2029E | O52: 2030E
B54: Cash & equivalents | C54: $M | G54: =Model!G72/1000 -> 244.385 | H54: =Model!H72/1000 -> 213.253 | I54: =Model!I72/1000 -> 764.307 | J54: =Model!J72/1000 -> 538.402 | K54: =Model!K72/1000 -> 312.62604 | L54: =Model!L72/1000 -> 348.44309 | M54: =Model!M72/1000 -> 664.67976 | N54: =Model!N72/1000 -> 1238.4583 | O54: =Model!O72/1000 -> 2010.0591
B55: Total assets | C55: $M | G55: =Model!G75/1000 -> 2037.979 | H55: =Model!H75/1000 -> 2598.003 | I55: =Model!I75/1000 -> 4232.372 | J55: =Model!J75/1000 -> 7112.853 | K55: =Model!K75/1000 -> 7905.1803 | L55: =Model!L75/1000 -> 8575.1552 | M55: =Model!M75/1000 -> 9329.0665 | N55: =Model!N75/1000 -> 10138.492 | O55: =Model!O75/1000 -> 10938.277
...

Sheet Imput Historical
B3: INCOME STATEMENT (P&L)
B5: Amounts expressed in thousands of US Dollars | G5: 2022 | H5: 2023 | I5: 2024 | J5: 2025
B7: Revenue from contracts with customers | G7: 1187660 | H7: 1168774 | I7: 1647768 | J7: 2474197
B9: Cost of sales
B11: Operating costs | G11: -133385 | H11: -94685 | I11: -116526 | J11: -186945
B12: Crude oil stock fluctuation | G12: -500 | H12: -2058 | I12: 1720 | J12: 1046
B13: Royalties and others | G13: -188677 | H13: -176813 | I13: -243950 | J13: -345349
B14: Depreciation, depletion and amortization | G14: -234862 | H14: -276430 | I14: -437699 | J14: -738903
B15: Other non-cash costs | G15: 0 | H15: -27539 | I15: -33570 | J15: -29016
B17: Gross profit | G17: 630236 | H17: 591249 | I17: 817743 | J17: 1175030
B19: Selling expenses | G19: -59904 | H19: -68792 | I19: -140334 | J19: -218072
B20: General and administrative expenses | G20: -63826 | H20: -70483 | I20: -108954 | J20: -147709
B21: Exploration expenses | G21: -736 | H21: -16 | I21: -138 | J21: -578
B22: Other operating income | G22: 26698 | H22: 203812 | I22: 54127 | J22: 512793
B23: Other operating expenses | G23: -3321 | H23: 302 | I23: -1261 | J23: -32382
B24: Impairment of long-lived assets | G24: 0 | H24: -24585 | I24: 4207 | J24: -38252
... B41: Profit for the year, net | G41: 269535 | H41: 396955 | I41: 477521 | J41: 719063
B43: Other comprehensive income
B45: Actuarial remeasurement | G45: -4181 | H45: 6565 | I45: -10200 | J45: 36
B46: Deferred income tax on OCI | G46: 1463 | H46: -2298 | I46: 3570 | J46: -13
B48: Other comprehensive income for the year | G48: -2718 | H48: 4267 | I48: -6630 | J48: 23
B50: Total comprehensive profit for the year | G50: 266817 | H50: 401222 | I50: 470891 | J50: 719086
B52: Earnings per share
B54: Basic (USD per share) | G54: 3.068 | H54: 4.237 | I54: 4.979 | J54: 7.015
B55: Diluted (USD per share) | G55: 2.755 | H55: 4 | I55: 4.633 | J55: 6.707
B58: CASH FLOW STATEMENT
B60: Amounts expressed in thousands of US Dollars | G60: 2022 | H60: 2023 | I60: 2024 | J60: 2025
B62: Cash flows from operating activities:
B63: Profit for the year, net | G63: 269535 | H63: 396955 | I63: 477521 | J63: 719063
B65: Adjustments to reconcile net cash flows
B66: Items related to operating activities:
B67: Allowance for expected credit losses | G67: -36 | H67: 0 | I67: 0 | J67: 44
B68: Share-based payments | G68: 16576 | H68: 23133 | I68: 34923 | J68: 55989
B69: Net increase in provisions | G69: 2790 | H69: -578 | I69: 1261 | J69: 2507
B70: Net changes in foreign exchange rate | G70: -33263 | H70: -18458 | I70: 453 | J70: 144
B71: Discount of assets and liabilities at present value | G71: 2561 | H71: -2137 | I71: -933 | J71: 23652
B72: Discount for well plugging and abandonment | G72: 2444 | H72: 2387 | I72: 1312 | J72: 2434
B73: Income tax expense | G73: 163979 | H73: 148404 | I73: 113306 | J73: 285608
B74: Other non-cash costs related to the transfer of conventional assets | G74: 0 | H74: 27539 | I74: 33570 | J74: 29016
B75: Employee benefits | G75: 502 | H75: 300 | I75: 489 | J75: 788
...

Sheet Imputs Drivers
B3: DRIVERS
B5: Driver Switch | C5: Base Case | G5: 2026E | H5: 2027E | I5: 2028E | J5: 2029E | K5: 2030E
B8: Brent Price ($/bbl) | G8: =INDEX(G10:G12,MATCH($C$5,$B$10:$B$12,0)) -> 85 | H8: =INDEX(H10:H12,MATCH($C$5,$B$10:$B$12,0)) -> 82 | I8: =INDEX(I10:I12,MATCH($C$5,$B$10:$B$12,0)) -> 80 | J8: =INDEX(J10:J12,MATCH($C$5,$B$10:$B$12,0)) -> 78 | K8: =INDEX(K10:K12,MATCH($C$5,$B$10:$B$12,0)) -> 75
B10: Best Case | G10: 95 | H10: 92 | I10: 90 | J10: 88 | K10: 85
B11: Base Case | G11: 85 | H11: 82 | I11: 80 | J11: 78 | K11: 75
B12: Worst Case | G12: 61.5 | H12: 64 | I12: 65.3 | J12: 63.4 | K12: 63.4
B14: Production Growth (% YoY) | G14: =INDEX(G16:G18,MATCH($C$5,$B$10:$B$12,0)) -> 0.15 | H14: =INDEX(H16:H18,MATCH($C$5,$B$10:$B$12,0)) -> 0.12 | I14: =INDEX(I16:I18,MATCH($C$5,$B$10:$B$12,0)) -> 0.1 | J14: =INDEX(J16:J18,MATCH($C$5,$B$10:$B$12,0)) -> 0.08 | K14: =INDEX(K16:K18,MATCH($C$5,$B$10:$B$12,0)) -> 0.06
B16: =$B$10 -> Best Case | G16: 0.25 | H16: 0.2 | I16: 0.15 | J16: 0.12 | K16: 0.1
B17: =$B$11 -> Base Case | G17: 0.15 | H17: 0.12 | I17: 0.1 | J17: 0.08 | K17: 0.06
B18: =$B$12 -> Worst Case | G18: 0.05 | H18: 0.05 | I18: 0.04 | J18: 0.04 | K18: 0.03
B20: Lifting Cost ($/boe) | G20: =INDEX(G22:G24,MATCH($C$5,$B$10:$B$12,0)) -> 4.3 | H20: =INDEX(H22:H24,MATCH($C$5,$B$10:$B$12,0)) -> 4.1 | I20: =INDEX(I22:I24,MATCH($C$5,$B$10:$B$12,0)) -> 3.9 | J20: =INDEX(J22:J24,MATCH($C$5,$B$10:$B$12,0)) -> 3.7 | K20: =INDEX(K22:K24,MATCH($C$5,$B$10:$B$12,0)) -> 3.5
B22: =$B$10 -> Best Case | G22: 3.8 | H22: 3.6 | I22: 3.4 | J22: 3.2 | K22: 3
B23: =$B$11 -> Base Case | G23: 4.3 | H23: 4.1 | I23: 3.9 | J23: 3.7 | K23: 3.5
B24: =$B$12 -> Worst Case | G24: 5 | H24: 4.8 | I24: 4.6 | J24: 4.4 | K24: 4.2
B26: CapEx ($M) | G26: =INDEX(G28:G30,MATCH($C$5,$B$10:$B$12,0)) -> 1550 | H26: =INDEX(H28:H30,MATCH($C$5,$B$10:$B$12,0)) -> 1500 | I26: =INDEX(I28:I30,MATCH($C$5,$B$10:$B$12,0)) -> 1400 | J26: =INDEX(J28:J30,MATCH($C$5,$B$10:$B$12,0)) -> 1300 | K26: =INDEX(K28:K30,MATCH($C$5,$B$10:$B$12,0)) -> 1200
B28: =$B$10 -> Best Case | G28: 1400 | H28: 1300 | I28: 1200 | J28: 1100 | K28: 1000
B29: =$B$11 -> Base Case | G29: 1550 | H29: 1500 | I29: 1400 | J29: 1300 | K29: 1200
B30: =$B$12 -> Worst Case | G30: 1700 | H30: 1650 | I30: 1600 | J30: 1500 | K30: 1400
B33: FINANCIAL & TAX ASSUMPTIONS
B34: (applied to all scenarios) | G34: 2026E | H34: 2027E | I34: 2028E | J34: 2029E | K34: 2030E
B36: Interest rate on gross debt (%) | G36: 0.075 | H36: 0.075 | I36: 0.075 | J36: 0.075 | K36: 0.075
B37: Interest rate earned on cash (%) | G37: 0.03 | H37: 0.03 | I37: 0.03 | J37: 0.03 | K37: 0.03
B38: Effective tax rate (%) | G38: 0.3 | H38: 0.3 | I38: 0.3 | J38: 0.3 | K38: 0.3
B39: Debt repayment ($M) | G39: 350 | H39: 350 | I39: 350 | J39: 350 | K39: 350
B40: New borrowings ($M) | G40: 0 | H40: 0 | I40: 0 | J40: 0 | K40: 0
B41: Minimum cash balance ($M) | G41: 200 | H41: 200 | I41: 200 | J41: 200 | K41: 200
B42: DD&A rate ($/boe) | G42: 17.5 | H42: 17.5 | I42: 17.5 | J42: 17.5 | K42: 17.5
B43: Sources / basis for the assumptions above:
B44: Interest rate 7.5% ≈ implied 2025A rate (interest expense 163,356 / average gross debt 2,301,322 = 7.1%). Source: Imput Historical rows 30, 192, 203.
B45: Effective tax rate 30.0% vs. historical 37.8% / 27.2% / 19.2% / 28.4% (2022–2025 avg 28.2%); Argentine statutory rate is 35%. Source: Imput Historical rows 35, 39.
B46: Debt repayment $350M/yr = 2025A current portion of borrowings (350,095 k); new borrowings set to zero. Source: Imput Historical row 203.
B47: Minimum cash $200M: below this level the model draws on a revolver (Model rows 176–179); excess cash above it repays the revolver first.
B48: DD&A rate $17.5/boe = 2025A implied rate (historical: 13.3 / 14.8 / 17.2 / 17.5). Source: Imput Historical row 222. Depletion is now volume-driven, not price-driven.

Sheet Model
B3: INCOME STATEMENT
B5: Amounts expressed in thousands of US Dollars | G5: 2022A | H5: 2023A | I5: 2024A | J5: 2025A | K5: 2026E | L5: 2027E | M5: 2028E | N5: 2029E | O5: 2030E
B7: Revenue from contracts with customers | G7: ='Imput Historical'!G7 -> 1187660 | H7: ='Imput Historical'!H7 -> 1168774 | I7: ='Imput Historical'!I7 -> 1647768 | J7: ='Imput Historical'!J7 -> 2474197 | K7: =J7*(1+'Imputs Drivers'!G14)*(K156/J156) -> 3546228.1 | L7: =K7*(1+'Imputs Drivers'!H14)*(L156/K156) -> 3831595.2 | M7: =L7*(1+'Imputs Drivers'!I14)*(M156/L156) -> 4111955.8 | N7: =M7*(1+'Imputs Drivers'!J14)*(N156/M156) -> 4329889.4 | O7: =N7*(1+'Imputs Drivers'!K14)*(O156/N156) -> 4413156.5
B9: Cost of sales
B11: Operating costs | G11: ='Imput Historical'!G11 -> -133385 | H11: ='Imput Historical'!H11 -> -94685 | I11: ='Imput Historical'!I11 -> -116526 | J11: ='Imput Historical'!J11 -> -186945 | K11: =J11*(1+'Imputs Drivers'!G14)*(K157/J157) -> -210100.69 | L11: =K11*(1+'Imputs Drivers'!H14)*(L157/K157) -> -224367.99 | M11: =L11*(1+'Imputs Drivers'!I14)*(M157/L157) -> -234765.53 | N11: =M11*(1+'Imputs Drivers'!J14)*(N157/M157) -> -240544.37 | O11: =N11*(1+'Imputs Drivers'!K14)*(O157/N157) -> -241194.49
B12: Crude oil stock fluctuation | G12: ='Imput Historical'!G12 -> -500 | H12: ='Imput Historical'!H12 -> -2058 | I12: ='Imput Historical'!I12 -> 1720 | J12: ='Imput Historical'!J12 -> 1046 | K12: 0 | L12: 0 | M12: 0 | N12: 0 | O12: 0
B13: Royalties and others | G13: ='Imput Historical'!G13 -> -188677 | H13: ='Imput Historical'!H13 -> -176813 | I13: ='Imput Historical'!I13 -> -243950 | J13: ='Imput Historical'!J13 -> -345349 | K13: =K7*($J$13/$J$7) -> -494983.35 | L13: =L7*($J$13/$J$7) -> -534814.96 | M13: =M7*($J$13/$J$7) -> -573947.76 | N13: =N7*($J$13/$J$7) -> -604366.99 | O13: =O7*($J$13/$J$7) -> -615989.43
B14: Depreciation, depletion and amortization | G14: ='Imput Historical'!G14 -> -234862 | H14: ='Imput Historical'!H14 -> -276430 | I14: ='Imput Historical'!I14 -> -437699 | J14: ='Imput Historical'!J14 -> -738903 | K14: =-K158*365*K159/1000 -> -848265.43 | L14: =-L158*365*L159/1000 -> -950057.28 | M14: =-M158*365*M159/1000 -> -1045063 | N14: =-N158*365*N159/1000 -> -1128668 | O14: =-O158*365*O159/1000 -> -1196388.1
B15: Other non-cash costs | G15: ='Imput Historical'!G15 -> 0 | H15: ='Imput Historical'!H15 -> -27539 | I15: ='Imput Historical'!I15 -> -33570 | J15: ='Imput Historical'!J15 -> -29016 | K15: 0 | L15: 0 | M15: 0 | N15: 0 | O15: 0
B17: Gross profit | G17: =G7+G11+G12+G13+G14+G15 -> 630236 | H17: =H7+H11+H12+H13+H14+H15 -> 591249 | I17: =I7+I11+I12+I13+I14+I15 -> 817743 | J17: =J7+J11+J12+J13+J14+J15 -> 1175030 | K17: =K7+K11+K12+K13+K14+K15 -> 1992878.6 | L17: =L7+L11+L12+L13+L14+L15 -> 2122354.9 | M17: =M7+M11+M12+M13+M14+M15 -> 2258179.5 | N17: =N7+N11+N12+N13+N14+N15 -> 2356310 | O17: =O7+O11+O12+O13+O14+O15 -> 2359584.5
B19: Selling expenses | G19: ='Imput Historical'!G19 -> -59904 | H19: ='Imput Historical'!H19 -> -68792 | I19: ='Imput Historical'!I19 -> -140334 | J19: ='Imput Historical'!J19 -> -218072 | K19: =K7*($J$19/$J$7) -> -312559.21 | L19: =L7*($J$19/$J$7) -> -337711.03 | M19: =M7*($J$19/$J$7) -> -362421.59 | N19: =N7*($J$19/$J$7) -> -381629.94 | O19: =O7*($J$19/$J$7) -> -388968.98
B20: General and administrative expenses | G20: ='Imput Historical'!G20 -> -63826 | H20: ='Imput Historical'!H20 -> -70483 | I20: ='Imput Historical'!I20 -> -108954 | J20: ='Imput Historical'!J20 -> -147709 | K20: =K7*($J$20/$J$7) -> -211709.01 | L20: =L7*($J$20/$J$7) -> -228745.36 | M20: =M7*($J$20/$J$7) -> -245482.83 | N20: =N7*($J$20/$J$7) -> -258493.42 | O20: =O7*($J$20/$J$7) -> -263464.45
B21: Exploration expenses | G21: ='Imput Historical'!G21 -> -736 | H21: ='Imput Historical'!H21 -> -16 | I21: ='Imput Historical'!I21 -> -138 | J21: ='Imput Historical'!J21 -> -578 | K21: 0 | L21: 0 | M21: 0 | N21: 0 | O21: 0
B22: Other operating income | G22: ='Imput Historical'!G22 -> 26698 | H22: ='Imput Historical'!H22 -> 203812 | I22: ='Imput Historical'!I22 -> 54127 | J22: ='Imput Historical'!J22 -> 512793 | K22: 0 | L22: 0 | M22: 0 | N22: 0 | O22: 0
B23: Other operating expenses | G23: ='Imput Historical'!G23 -> -3321 | H23: ='Imput Historical'!H23 -> 302 | I23: ='Imput Historical'!I23 -> -1261 | J23: ='Imput Historical'!J23 -> -32382 | K23: 0 | L23: 0 | M23: 0 | N23: 0 | O23: 0
B24: Impairment of long-lived assets | G24: ='Imput Historical'!G24 -> 0 | H24: ='Imput Historical'!H24 -> -24585 | I24: ='Imput Historical'!I24 -> 4207 | J24: ='Imput Historical'!J24 -> -38252 | K24: 0 | L24: 0 | M24: 0 | N24: 0 | O24: 0
B26: Adjusted EBITDA (excl. other operating income / expenses) | G26: =G27-G14-G15-G24-G22-G23 -> 740632 | H26: =H27-H14-H15-H24-H22-H23 -> 755927 | I26: =I27-I14-I15-I24-I22-I23 -> 1039586 | J26: =J27-J14-J15-J24-J22-J23 -> 1576590 | K26: =K27-K14-K15-K24-K22-K23 -> 2316875.8 | L26: =L27-L14-L15-L24-L22-L23 -> 2505955.8 | M26: =M27-M14-M15-M24-M22-M23 -> 2695338.1 | N26: =N27-N14-N15-N24-N22-N23 -> 2844854.7 | O26: =O27-O14-O15-O24-O22-O23 -> 2903539.2
B27: EBIT / Operating profit | G27: =G17+G19+G20+G21+G22+G23+G24 -> 529147 | H27: =H17+H19+H20+H21+H22+H23+H24 -> 631487 | I27: =I17+I19+I20+I21+I22+I23+I24 -> 625390 | J27: =J17+J19+J20+J21+J22+J23+J24 -> 1250830 | K27: =K17+K19+K20+K21+K22+K23+K24 -> 1468610.4 | L27: =L17+L19+L20+L21+L22+L23+L24 -> 1555898.5 | M27: =M17+M19+M20+M21+M22+M23+M24 -> 1650275.1 | N27: =N17+N19+N20+N21+N22+N23+N24 -> 1716186.7 | O27: =O17+O19+O20+O21+O22+O23+O24 -> 1707151.1
B29: Income (loss) from investments in associates | G29: ='Imput Historical'!G28 -> 0 | H29: ='Imput Historical'!H28 -> 0 | I29: ='Imput Historical'!I28 -> 0 | J29: ='Imput Historical'!J28 -> -5214 | K29: 0 | L29: 0 | M29: 0 | N29: 0 | O29: 0
B30: Interest income | G30: ='Imput Historical'!G29 -> 809 | H30: ='Imput Historical'!H29 -> 1235 | I30: ='Imput Historical'!I29 -> 4535 | J30: ='Imput Historical'!J29 -> 10594 | K30: =K173 -> 16152.06 | L30: =L173 -> 9378.7812 | M30: =M173 -> 10453.293 | N30: =N173 -> 19940.393 | O30: =O173 -> 37153.748
B31: Interest expense | G31: ='Imput Historical'!G30 -> -28886 | H31: ='Imput Historical'!H30 -> -21879 | I31: ='Imput Historical'!I30 -> -62499 | J31: ='Imput Historical'!J30 -> -163356 | K31: =K172 -> -236555.77 | L31: =L172 -> -210305.77 | M31: =M172 -> -184055.77 | N31: =N172 -> -157805.77 | O31: =O172 -> -131555.77
B32: Other financial income (expense) | G32: ='Imput Historical'!G31 -> -67556 | H32: ='Imput Historical'!H31 -> -65484 | I32: ='Imput Historical'!I31 -> 23401 | J32: ='Imput Historical'!J31 -> -88183 | K32: 0 | L32: 0 | M32: 0 | N32: 0 | O32: 0
B34: Financial income (expense), net | G34: =SUM(G30:G32) -> -95633 | H34: =SUM(H30:H32) -> -86128 | I34: =SUM(I30:I32) -> -34563 | J34: =SUM(J30:J32) -> -240945 | K34: =SUM(K30:K32) -> -220403.71 | L34: =SUM(L30:L32) -> -200926.99 | M34: =SUM(M30:M32) -> -173602.48 | N34: =SUM(N30:N32) -> -137865.38 | O34: =SUM(O30:O32) -> -94402.027
B36: Profit before income tax | G36: =G27+G29+G34 -> 433514 | H36: =H27+H29+H34 -> 545359 | I36: =I27+I29+I34 -> 590827 | J36: =J27+J29+J34 -> 1004671 | K36: =K27+K29+K34 -> 1248206.7 | L36: =L27+L29+L34 -> 1354971.6 | M36: =M27+M29+M34 -> 1476672.6 | N36: =N27+N29+N34 -> 1578321.3 | O36: =O27+O29+O34 -> 1612749
B38: Current income tax (expense) | G38: ='Imput Historical'!G37 -> -92089 | H38: ='Imput Historical'!H37 -> -16393 | I38: ='Imput Historical'!I37 -> -426288 | J38: ='Imput Historical'!J37 -> -241657 | K38: =-K36*'Imputs Drivers'!G38 -> -374462.01 | L38: =-L36*'Imputs Drivers'!H38 -> -406491.47 | M38: =-M36*'Imputs Drivers'!I38 -> -443001.78 | N38: =-N36*'Imputs Drivers'!J38 -> -473496.39 | O38: =-O36*'Imputs Drivers'!K38 -> -483824.71
B39: Deferred income tax (expense) benefit | G39: ='Imput Historical'!G38 -> -71890 | H39: ='Imput Historical'!H38 -> -132011 | I39: ='Imput Historical'!I38 -> 312982 | J39: ='Imput Historical'!J38 -> -43951 | K39: 0 | L39: 0 | M39: 0 | N39: 0 | O39: 0
B40: Income tax (expense) | G40: =G38+G39 -> -163979 | H40: =H38+H39 -> -148404 | I40: =I38+I39 -> -113306 | J40: =J38+J39 -> -285608 | K40: =K38+K39 -> -374462.01 | L40: =L38+L39 -> -406491.47 | M40: =M38+M39 -> -443001.78 | N40: =N38+N39 -> -473496.39 | O40: =O38+O39 -> -483824.71
B42: Profit for the year, net | G42: =G36+G40 -> 269535 | H42: =H36+H40 -> 396955 | I42: =I36+I40 -> 477521 | J42: =J36+J40 -> 719063 | K42: =K36+K40 -> 873744.69 | L42: =L36+L40 -> 948480.09 | M42: =M36+M40 -> 1033670.8 | N42: =N36+N40 -> 1104824.9 | O42: =O36+O40 -> 1128924.3
B44: Earnings per share
B46: Basic (USD per share) | G46: ='Imput Historical'!G54 -> 3.068 | H46: ='Imput Historical'!H54 -> 4.237 | I46: ='Imput Historical'!I54 -> 4.979 | J46: ='Imput Historical'!J54 -> 7.015 | K46: =K42*$J$46/$J$42 -> 8.5240361 | L46: =L42*$J$46/$J$42 -> 9.2531361 | M46: =M42*$J$46/$J$42 -> 10.084236 | N46: =N42*$J$46/$J$42 -> 10.778397 | O46: =O42*$J$46/$J$42 -> 11.013505
B47: Diluted (USD per share) | G47: ='Imput Historical'!G55 -> 2.755 | H47: ='Imput Historical'!H55 -> 4 | I47: ='Imput Historical'!I55 -> 4.633 | J47: ='Imput Historical'!J55 -> 6.707 | K47: =K42*$J$47/$J$42 -> 8.1497805 | L47: =L42*$J$47/$J$42 -> 8.8468687 | M47: =M42*$J$47/$J$42 -> 9.641478 | N47: =N42*$J$47/$J$42 -> 10.305162 | O47: =O42*$J$47/$J$42 -> 10.529947
B50: BALANCE SHEET
B52: Amounts expressed in thousands of US Dollars | G52: 2022A | H52: 2023A | I52: 2024A | J52: 2025A | K52: 2026E | L52: 2027E | M52: 2028E | N52: 2029E | O52: 2030E
B54: Assets
B55: Noncurrent assets
B57: Property, plant and equipment | G57: ='Imput Historical'!G154 -> 1606339 | H57: ='Imput Historical'!H154 -> 1927759 | I57: ='Imput Historical'!I154 -> 2805983 | J57: ='Imput Historical'!J154 -> 5543032 | K57: =J57+'Imputs Drivers'!G26*1000+K14 -> 6244766.6 | L57: =K57+'Imputs Drivers'!H26*1000+L14 -> 6794709.3 | M57: =L57+'Imputs Drivers'!I26*1000+M14 -> 7149646.3 | N57: =M57+'Imputs Drivers'!J26*1000+N14 -> 7320978.2 | O57: =N57+'Imputs Drivers'!K26*1000+O14 -> 7324590.1
B58: Goodwill | G58: ='Imput Historical'!G155 -> 28288 | H58: ='Imput Historical'!H155 -> 22576 | I58: ='Imput Historical'!I155 -> 22576 | J58: ='Imput Historical'!J155 -> 22576 | K58: =J58 -> 22576 | L58: =K58 -> 22576 | M58: =L58 -> 22576 | N58: =M58 -> 22576 | O58: =N58 -> 22576
B59: Other intangible assets | G59: ='Imput Historical'!G156 -> 6792 | H59: ='Imput Historical'!H156 -> 10026 | I59: ='Imput Historical'!I156 -> 15443 | J59: ='Imput Historical'!J156 -> 18485 | K59: =J59 -> 18485 | L59: =K59 -> 18485 | M59: =L59 -> 18485 | N59: =M59 -> 18485 | O59: =N59 -> 18485
B60: Right-of-use assets | G60: ='Imput Historical'!G157 -> 26228 | H60: ='Imput Historical'!H157 -> 61025 | I60: ='Imput Historical'!I157 -> 105333 | J60: ='Imput Historical'!J157 -> 153283 | K60: =J60 -> 153283 | L60: =K60 -> 153283 | M60: =L60 -> 153283 | N60: =M60 -> 153283 | O60: =N60 -> 153283
B61: Biological assets | G61: ='Imput Historical'!G158 -> 0 | H61: ='Imput Historical'!H158 -> 0 | I61: ='Imput Historical'!I158 -> 10027 | J61: ='Imput Historical'!J158 -> 15855 | K61: =J61 -> 15855 | L61: =K61 -> 15855 | M61: =L61 -> 15855 | N61: =M61 -> 15855 | O61: =N61 -> 15855
...
